#VRML_SIM R2025a utf8

EXTERNPROTO "https://raw.githubusercontent.com/cyberbotics/webots/R2025a/projects/objects/road/protos/Road.proto"

WorldInfo {
  title "AI Racer Demo"
}
Viewpoint {
  orientation -0.5773502691896258 0.5773502691896258 0.5773502691896258 2.0944
  position 0 4.9666891932888514e-15 33.54101966249685
}
Background {
  skyColor [
    0.4 0.7 1
  ]
}
DirectionalLight {
  direction 1 1 -2
  intensity 1.5
}
Solid {
  translation 0 0 -0.1
  children [
    Shape {
      appearance PBRAppearance {
        baseColor 0.15 0.15 0.15
        roughness 0.95
        metalness 0
      }
      geometry Box {
        size 120 100 0.2
      }
    }
  ]
  name "ground"
  boundingObject Box {
    size 120 100 0.2
  }
}
Solid {
  translation 0 0 0.002
  children [
    Shape {
      appearance PBRAppearance {
      }
      geometry Box {
        size 0.3 8 0.004
      }
    }
  ]
  name "start_finish_line"
}
Solid {
  translation 25 5 0.3
  children [
    Shape {
      appearance PBRAppearance {
        baseColor 0.9 0.7 0.1
      }
      geometry Box {
        size 60 0.3 0.6
      }
    }
  ]
  name "wall_north"
  boundingObject Box {
    size 60 0.3 0.6
  }
}
Solid {
  translation 25 -45 0.3
  children [
    Shape {
      appearance PBRAppearance {
        baseColor 0.9 0.7 0.1
      }
      geometry Box {
        size 60 0.3 0.6
      }
    }
  ]
  name "wall_south"
  boundingObject Box {
    size 60 0.3 0.6
  }
}
Solid {
  translation 52 -20 0.3
  children [
    Shape {
      appearance PBRAppearance {
        baseColor 0.9 0.7 0.1
      }
      geometry Box {
        size 0.3 50 0.6
      }
    }
  ]
  name "wall_east"
  boundingObject Box {
    size 0.3 50 0.6
  }
}
Solid {
  translation -4 -20 0.3
  children [
    Shape {
      appearance PBRAppearance {
        baseColor 0.9 0.7 0.1
      }
      geometry Box {
        size 0.3 50 0.6
      }
    }
  ]
  name "wall_west"
  boundingObject Box {
    size 0.3 50 0.6
  }
}
Robot {
  children [
    Camera {
      translation 24 -20 60
      rotation 0 1 0 1.5708
      name "overhead_cam"
      fieldOfView 1.1
      width 640
      height 480
    }
  ]
  name "supervisor"
  controller "supervisor"
  supervisor TRUE
}
DEF car_1 Robot {
  translation -3 -0.5 0.04
  children [
    Shape {
      appearance PBRAppearance {
        baseColor 1 0.1 0.1
        roughness 0.5
        metalness 0.1
      }
      geometry Box {
        size 0.6 0.4 0.06
      }
    }
    HingeJoint {
      jointParameters HingeJointParameters {
        axis 0 1 0
        anchor -0.2 -0.22 0
      }
      device [
        RotationalMotor {
          name "left_motor"
          maxVelocity 40
        }
      ]
      endPoint Solid {
        translation -0.2 -0.22 0
        rotation 1 0 0 1.5708
        children [
          Shape {
            appearance PBRAppearance {
              baseColor 0.1 0.1 0.1
            }
            geometry Cylinder {
              height 0.04
              radius 0.04
            }
          }
        ]
        name "c1_rl"
        boundingObject Cylinder {
          height 0.04
          radius 0.04
        }
        physics Physics {
        }
      }
    }
    HingeJoint {
      jointParameters HingeJointParameters {
        axis 0 1 0
        anchor -0.2 0.22 0
      }
      device [
        RotationalMotor {
          name "right_motor"
          maxVelocity 40
        }
      ]
      endPoint Solid {
        translation -0.2 0.22 0
        rotation 1 0 0 1.5708
        children [
          Shape {
            appearance PBRAppearance {
              baseColor 0.1 0.1 0.1
            }
            geometry Cylinder {
              height 0.04
              radius 0.04
            }
          }
        ]
        name "c1_rr"
        boundingObject Cylinder {
          height 0.04
          radius 0.04
        }
        physics Physics {
        }
      }
    }
    HingeJoint {
      jointParameters HingeJointParameters {
        axis 0 1 0
        anchor 0.2 -0.22 0
      }
      endPoint Solid {
        translation 0.2 -0.22 0
        rotation 1 0 0 1.5708
        children [
          Shape {
            appearance PBRAppearance {
              baseColor 0.1 0.1 0.1
            }
            geometry Cylinder {
              height 0.04
              radius 0.04
            }
          }
        ]
        name "c1_fl"
        boundingObject Cylinder {
          height 0.04
          radius 0.04
        }
        physics Physics {
        }
      }
    }
    HingeJoint {
      jointParameters HingeJointParameters {
        axis 0 1 0
        anchor 0.2 0.22 0
      }
      endPoint Solid {
        translation 0.2 0.22 0
        rotation 1 0 0 1.5708
        children [
          Shape {
            appearance PBRAppearance {
              baseColor 0.1 0.1 0.1
            }
            geometry Cylinder {
              height 0.04
              radius 0.04
            }
          }
        ]
        name "c1_fr"
        boundingObject Cylinder {
          height 0.04
          radius 0.04
        }
        physics Physics {
        }
      }
    }
    Camera {
      translation 0.32 -0.1 0.04
      name "left_camera"
      fieldOfView 1.047
      width 640
      height 480
    }
    Camera {
      translation 0.32 0.1 0.04
      name "right_camera"
      fieldOfView 1.047
      width 640
      height 480
    }
  ]
  name "car_1"
  boundingObject Box {
    size 0.6 0.4 0.06
  }
  physics Physics {
    density -1
    mass 1
  }
  controller "car"
}
DEF car_2 Robot {
  translation -3 0.5 0.04
  children [
    Shape {
      appearance PBRAppearance {
        baseColor 0.1 0.2 1
        roughness 0.5
        metalness 0.1
      }
      geometry Box {
        size 0.6 0.4 0.06
      }
    }
    HingeJoint {
      jointParameters HingeJointParameters {
        axis 0 1 0
        anchor -0.2 -0.22 0
      }
      device [
        RotationalMotor {
          name "left_motor"
          maxVelocity 40
        }
      ]
      endPoint Solid {
        translation -0.2 -0.22 0
        rotation 1 0 0 1.5708
        children [
          Shape {
            appearance PBRAppearance {
              baseColor 0.1 0.1 0.1
            }
            geometry Cylinder {
              height 0.04
              radius 0.04
            }
          }
        ]
        name "c2_rl"
        boundingObject Cylinder {
          height 0.04
          radius 0.04
        }
        physics Physics {
        }
      }
    }
    HingeJoint {
      jointParameters HingeJointParameters {
        axis 0 1 0
        anchor -0.2 0.22 0
      }
      device [
        RotationalMotor {
          name "right_motor"
          maxVelocity 40
        }
      ]
      endPoint Solid {
        translation -0.2 0.22 0
        rotation 1 0 0 1.5708
        children [
          Shape {
            appearance PBRAppearance {
              baseColor 0.1 0.1 0.1
            }
            geometry Cylinder {
              height 0.04
              radius 0.04
            }
          }
        ]
        name "c2_rr"
        boundingObject Cylinder {
          height 0.04
          radius 0.04
        }
        physics Physics {
        }
      }
    }
    HingeJoint {
      jointParameters HingeJointParameters {
        axis 0 1 0
        anchor 0.2 -0.22 0
      }
      endPoint Solid {
        translation 0.2 -0.22 0
        rotation 1 0 0 1.5708
        children [
          Shape {
            appearance PBRAppearance {
              baseColor 0.1 0.1 0.1
            }
            geometry Cylinder {
              height 0.04
              radius 0.04
            }
          }
        ]
        name "c2_fl"
        boundingObject Cylinder {
          height 0.04
          radius 0.04
        }
        physics Physics {
        }
      }
    }
    HingeJoint {
      jointParameters HingeJointParameters {
        axis 0 1 0
        anchor 0.2 0.22 0
      }
      endPoint Solid {
        translation 0.2 0.22 0
        rotation 1 0 0 1.5708
        children [
          Shape {
            appearance PBRAppearance {
              baseColor 0.1 0.1 0.1
            }
            geometry Cylinder {
              height 0.04
              radius 0.04
            }
          }
        ]
        name "c2_fr"
        boundingObject Cylinder {
          height 0.04
          radius 0.04
        }
        physics Physics {
        }
      }
    }
    Camera {
      translation 0.32 -0.1 0.04
      name "left_camera"
      fieldOfView 1.047
      width 640
      height 480
    }
    Camera {
      translation 0.32 0.1 0.04
      name "right_camera"
      fieldOfView 1.047
      width 640
      height 480
    }
  ]
  name "car_2"
  boundingObject Box {
    size 0.6 0.4 0.06
  }
  physics Physics {
    density -1
    mass 1
  }
  controller "car"
}
DEF car_3 Robot {
  translation -5 -0.5 0.04
  children [
    Shape {
      appearance PBRAppearance {
        baseColor 0.1 0.9 0.2
        roughness 0.5
        metalness 0.1
      }
      geometry Box {
        size 0.6 0.4 0.06
      }
    }
    HingeJoint {
      jointParameters HingeJointParameters {
        axis 0 1 0
        anchor -0.2 -0.22 0
      }
      device [
        RotationalMotor {
          name "left_motor"
          maxVelocity 40
        }
      ]
      endPoint Solid {
        translation -0.2 -0.22 0
        rotation 1 0 0 1.5708
        children [
          Shape {
            appearance PBRAppearance {
              baseColor 0.1 0.1 0.1
            }
            geometry Cylinder {
              height 0.04
              radius 0.04
            }
          }
        ]
        name "c3_rl"
        boundingObject Cylinder {
          height 0.04
          radius 0.04
        }
        physics Physics {
        }
      }
    }
    HingeJoint {
      jointParameters HingeJointParameters {
        axis 0 1 0
        anchor -0.2 0.22 0
      }
      device [
        RotationalMotor {
          name "right_motor"
          maxVelocity 40
        }
      ]
      endPoint Solid {
        translation -0.2 0.22 0
        rotation 1 0 0 1.5708
        children [
          Shape {
            appearance PBRAppearance {
              baseColor 0.1 0.1 0.1
            }
            geometry Cylinder {
              height 0.04
              radius 0.04
            }
          }
        ]
        name "c3_rr"
        boundingObject Cylinder {
          height 0.04
          radius 0.04
        }
        physics Physics {
        }
      }
    }
    HingeJoint {
      jointParameters HingeJointParameters {
        axis 0 1 0
        anchor 0.2 -0.22 0
      }
      endPoint Solid {
        translation 0.2 -0.22 0
        rotation 1 0 0 1.5708
        children [
          Shape {
            appearance PBRAppearance {
              baseColor 0.1 0.1 0.1
            }
            geometry Cylinder {
              height 0.04
              radius 0.04
            }
          }
        ]
        name "c3_fl"
        boundingObject Cylinder {
          height 0.04
          radius 0.04
        }
        physics Physics {
        }
      }
    }
    HingeJoint {
      jointParameters HingeJointParameters {
        axis 0 1 0
        anchor 0.2 0.22 0
      }
      endPoint Solid {
        translation 0.2 0.22 0
        rotation 1 0 0 1.5708
        children [
          Shape {
            appearance PBRAppearance {
              baseColor 0.1 0.1 0.1
            }
            geometry Cylinder {
              height 0.04
              radius 0.04
            }
          }
        ]
        name "c3_fr"
        boundingObject Cylinder {
          height 0.04
          radius 0.04
        }
        physics Physics {
        }
      }
    }
    Camera {
      translation 0.32 -0.1 0.04
      name "left_camera"
      fieldOfView 1.047
      width 640
      height 480
    }
    Camera {
      translation 0.32 0.1 0.04
      name "right_camera"
      fieldOfView 1.047
      width 640
      height 480
    }
  ]
  name "car_3"
  boundingObject Box {
    size 0.6 0.4 0.06
  }
  physics Physics {
    density -1
    mass 1
  }
  controller "car"
}
DEF car_4 Robot {
  translation -5 0.5 0.04
  children [
    Shape {
      appearance PBRAppearance {
        baseColor 1 0.9 0.1
        roughness 0.5
        metalness 0.1
      }
      geometry Box {
        size 0.6 0.4 0.06
      }
    }
    HingeJoint {
      jointParameters HingeJointParameters {
        axis 0 1 0
        anchor -0.2 -0.22 0
      }
      device [
        RotationalMotor {
          name "left_motor"
          maxVelocity 40
        }
      ]
      endPoint Solid {
        translation -0.2 -0.22 0
        rotation 1 0 0 1.5708
        children [
          Shape {
            appearance PBRAppearance {
              baseColor 0.1 0.1 0.1
            }
            geometry Cylinder {
              height 0.04
              radius 0.04
            }
          }
        ]
        name "c4_rl"
        boundingObject Cylinder {
          height 0.04
          radius 0.04
        }
        physics Physics {
        }
      }
    }
    HingeJoint {
      jointParameters HingeJointParameters {
        axis 0 1 0
        anchor -0.2 0.22 0
      }
      device [
        RotationalMotor {
          name "right_motor"
          maxVelocity 40
        }
      ]
      endPoint Solid {
        translation -0.2 0.22 0
        rotation 1 0 0 1.5708
        children [
          Shape {
            appearance PBRAppearance {
              baseColor 0.1 0.1 0.1
            }
            geometry Cylinder {
              height 0.04
              radius 0.04
            }
          }
        ]
        name "c4_rr"
        boundingObject Cylinder {
          height 0.04
          radius 0.04
        }
        physics Physics {
        }
      }
    }
    HingeJoint {
      jointParameters HingeJointParameters {
        axis 0 1 0
        anchor 0.2 -0.22 0
      }
      endPoint Solid {
        translation 0.2 -0.22 0
        rotation 1 0 0 1.5708
        children [
          Shape {
            appearance PBRAppearance {
              baseColor 0.1 0.1 0.1
            }
            geometry Cylinder {
              height 0.04
              radius 0.04
            }
          }
        ]
        name "c4_fl"
        boundingObject Cylinder {
          height 0.04
          radius 0.04
        }
        physics Physics {
        }
      }
    }
    HingeJoint {
      jointParameters HingeJointParameters {
        axis 0 1 0
        anchor 0.2 0.22 0
      }
      endPoint Solid {
        translation 0.2 0.22 0
        rotation 1 0 0 1.5708
        children [
          Shape {
            appearance PBRAppearance {
              baseColor 0.1 0.1 0.1
            }
            geometry Cylinder {
              height 0.04
              radius 0.04
            }
          }
        ]
        name "c4_fr"
        boundingObject Cylinder {
          height 0.04
          radius 0.04
        }
        physics Physics {
        }
      }
    }
    Camera {
      translation 0.32 -0.1 0.04
      name "left_camera"
      fieldOfView 1.047
      width 640
      height 480
    }
    Camera {
      translation 0.32 0.1 0.04
      name "right_camera"
      fieldOfView 1.047
      width 640
      height 480
    }
  ]
  name "car_4"
  boundingObject Box {
    size 0.6 0.4 0.06
  }
  physics Physics {
    density -1
    mass 1
  }
  controller "car"
}
Road {
  translation 8 4 6
  rotation 0.7548294124240689 0.6469966392206304 0.10783277320343841 0.05
}
